Error occurred during training. Error: Invalid schema: 1 validation error for SchemaModel
staticCovariates
  field required (type=value_error.missing)
Traceback (most recent call last):
  File "C:\Users\abbus\Documents\GitRepos\rt_repos\rt-models\forecasting\rt_forecasting_nbeats\src\data_models\schema_validator.py", line 162, in validate_schema_dict
    schema_dict = SchemaModel.parse_obj(schema_dict).dict()
                  ^^^^^^^^^^^^^^^^^^^^^^^^^^^^^^^^^^
  File "pydantic\main.py", line 526, in pydantic.main.BaseModel.parse_obj
  File "pydantic\main.py", line 341, in pydantic.main.BaseModel.__init__
pydantic.error_wrappers.ValidationError: 1 validation error for SchemaModel
staticCovariates
  field required (type=value_error.missing)

The above exception was the direct cause of the following exception:

Traceback (most recent call last):
  File "C:\Users\abbus\Documents\GitRepos\rt_repos\rt-models\forecasting\rt_forecasting_nbeats\src\train.py", line 59, in run_training
    data_schema = load_json_data_schema(input_schema_dir)
                  ^^^^^^^^^^^^^^^^^^^^^^^^^^^^^^^^^^^^^^^
  File "C:\Users\abbus\Documents\GitRepos\rt_repos\rt-models\forecasting\rt_forecasting_nbeats\src\schema\data_schema.py", line 355, in load_json_data_schema
    validated_schema_dict = validate_schema_dict(schema_dict=schema_dict)
                            ^^^^^^^^^^^^^^^^^^^^^^^^^^^^^^^^^^^^^^^^^^^^^
  File "C:\Users\abbus\Documents\GitRepos\rt_repos\rt-models\forecasting\rt_forecasting_nbeats\src\data_models\schema_validator.py", line 165, in validate_schema_dict
    raise ValueError(f"Invalid schema: {exc}") from exc
ValueError: Invalid schema: 1 validation error for SchemaModel
staticCovariates
  field required (type=value_error.missing)
